<?xml version="1.0"?>
<robot xmlns:xacro="http://ros.org/wiki/xacro">
<xacro:macro name="abb_irb120" params="prefix">
  <!-- link list -->
  <link name="${prefix}base_link">
    <inertial>
      <mass value="6.215"/>
      <origin xyz="-0.042039286 8.0131669E-05 0.079637532" rpy="0 0 0"/>
      <inertia ixx="0.024727161" ixy="-8.078424E-05" ixz="0.0013090238" iyy="0.049128491" iyz="-8.0419046E-06" izz="0.047237615"/>
    </inertial> 
    <visual>
      <origin xyz="0 0 0" rpy="0 0 0"/>
      <geometry>
        <mesh filename="package://abb_irb120_support/meshes/irb120/visual/base_link.stl"/>
      </geometry>
      <material name="abb_orange">
        <color rgba="1 0.43 0 1"/>
      </material>      
    </visual>
    <collision>
      <origin xyz="0 0 0" rpy="0 0 0"/>
      <geometry>
        <mesh filename="package://abb_irb120_support/meshes/irb120/collision/base_link.stl"/>
      </geometry>
      <material name="yellow">
        <color rgba="0 1 1 1"/>
      </material>      
    </collision>
  </link>
  <link name="${prefix}link_1">
    <inertial>
      <mass value="3.067" />
      <origin xyz="9.7686412E-05 -0.00011929533 0.23841183" rpy="0 0 0"/>
      <inertia ixx="0.014217456" ixy="-1.2857888E-05" ixz="-2.3136423E-05" iyy="0.014404147" iyz="1.9340368E-05" izz="0.010453301"/>
    </inertial>
    <visual>
      <origin xyz="0 0 0" rpy="0 0 0"/>
      <geometry>
        <mesh filename="package://abb_irb120_support/meshes/irb120/visual/link_1.stl"/>
      </geometry>
      <material name="abb_orange"/>      
    </visual>
    <collision>
      <origin xyz="0 0 0" rpy="0 0 0"/>
      <geometry>
        <mesh filename="package://abb_irb120_support/meshes/irb120/collision/link_1.stl"/>
      </geometry>
      <material name="yellow"/>
    </collision>
  </link>
  <link name="${prefix}link_2">
    <inertial>
      <mass value="3.908667"/>
      <origin xyz="0.00077829178 -0.0021170276 0.1012432" rpy="0 0 0"/>
      <inertia ixx="0.060311109" ixy="9.8343135E-06" ixz="5.7240689E-05" iyy="0.04156899" iyz="-0.00050497005" izz="0.025954849"/>
    </inertial>
    <visual>
      <origin xyz="0 0 0" rpy="0 0 0"/>
      <geometry>
        <mesh filename="package://abb_irb120_support/meshes/irb120/visual/link_2.stl"/>
      </geometry>
      <material name="abb_orange"/>
    </visual>
    <collision>
      <origin xyz="0 0 0" rpy="0 0 0"/>
      <geometry>
        <mesh filename="package://abb_irb120_support/meshes/irb120/collision/link_2.stl"/>
      </geometry>
      <material name="yellow"/>
    </collision>
  </link>
  <link name="${prefix}link_3">
    <inertial>
      <mass value="2.94372"/>
      <origin xyz="0.022807656 0.0010643596 0.057910651" rpy="0 0 0"/>
      <inertia ixx="0.0083560552" ixy="-8.0154465E-05" ixz="0.0014288355" iyy="0.016712978" iyz="-0.00018222659" izz="0.012698447"/>
    </inertial>
    <visual>
      <origin xyz="0 0 0" rpy="0 0 0"/>
      <geometry>
        <mesh filename="package://abb_irb120_support/meshes/irb120/visual/link_3.stl"/>
      </geometry>
      <material name="abb_orange"/>
    </visual>
    <collision>
      <origin xyz="0 0 0" rpy="0 0 0"/>
      <geometry>
        <mesh filename="package://abb_irb120_support/meshes/irb120/collision/link_3.stl"/>
      </geometry>
      <material name="yellow"/>
    </collision>
  </link>
  <link name="${prefix}link_4">
    <inertial>
      <mass value="1.3278642"/>
      <origin xyz="0.22470384 0.00015341817 0.00040552537" rpy="0 0 0"/>
      <inertia ixx="0.0028466109" ixy="-2.1276535E-05" ixz="-1.643522E-05" iyy="0.0040134585" iyz="1.313359E-05" izz="0.0052535097"/>
    </inertial>
    <visual>
      <origin xyz="0 0 0" rpy="0 0 0"/>
      <geometry>
        <mesh filename="package://abb_irb120_support/meshes/irb120/visual/link_4.stl"/>
      </geometry>
      <material name="abb_orange"/>
    </visual>
    <collision>
      <origin xyz="0 0 0" rpy="0 0 0"/>
      <geometry>
        <mesh filename="package://abb_irb120_support/meshes/irb120/collision/link_4.stl"/>
      </geometry>
      <material name="yellow"/>
    </collision>
  </link>
  <link name="${prefix}link_5">
    <inertial>
      <mass value="0.54662685"/>
      <origin xyz="-0.0010948374 3.6852479E-05 6.2216732E-05" rpy="0 0 0"/>
      <inertia ixx="0.00040489103" ixy="1.6194294E-06" ixz="8.4680493E-07" iyy="0.00089282497" iyz="-1.5179204E-08" izz="0.00081546839"/>
    </inertial>
    <visual>
      <origin xyz="0 0 0" rpy="0 0 0"/>
      <geometry>
        <mesh filename="package://abb_irb120_support/meshes/irb120/visual/link_5.stl"/>
      </geometry>
      <material name="abb_orange"/>
    </visual>
    <collision>
      <origin xyz="0 0 0" rpy="0 0 0"/>
      <geometry>
        <mesh filename="package://abb_irb120_support/meshes/irb120/collision/link_5.stl"/>
      </geometry>
      <material name="yellow"/>
    </collision>
  </link>
  <link name="${prefix}link_6">
    <inertial>
      <mass value="0.01367842"/>
      <origin xyz="-0.0070620873 -0.00016958101 -1.3236698E-06" rpy="0 0 0"/>
      <inertia ixx="0.001" ixy="0" ixz="0" iyy="0.001" iyz="0" izz="0.001"/>
    </inertial>
    <visual>
      <origin xyz="0 0 0" rpy="0 0 0"/>
      <geometry>
        <mesh filename="package://abb_irb120_support/meshes/irb120/visual/link_6.stl"/>
      </geometry>
      <material name="black">
        <color rgba="0 0 0 1"/>
      </material>  
    </visual>
    <collision>
      <origin xyz="0 0 0" rpy="0 0 0"/>
      <geometry>
        <mesh filename="package://abb_irb120_support/meshes/irb120/collision/link_6.stl"/>
      </geometry>
      <material name="yellow"/>
    </collision>
  </link>
  <link name="${prefix}tool0"/>
  <!-- end of link list -->

  <!-- joint list -->
  <joint name="${prefix}joint_1" type="revolute">
    <origin rpy="0 0 0" xyz="0 0 0"/>
    <parent link="${prefix}base_link"/>
    <child link="${prefix}link_1"/>
    <limit effort="100" lower="-2.87979" upper="2.87979" velocity="4.36332"/>
    <axis xyz="0 0 1"/>
    <dynamics damping="0.0" friction="0.0"/>
  </joint>
  <joint name="${prefix}joint_2" type="revolute">
    <origin rpy="0 0 0" xyz="0 0 0.29"/>
    <parent link="${prefix}link_1"/>
    <child link="${prefix}link_2"/>
    <limit effort="100" lower="-1.91986" upper="1.91986" velocity="4.36332"/>
    <axis xyz="0 1 0"/>
    <dynamics damping="0.0" friction="0.0"/>
  </joint>
  <joint name="${prefix}joint_3" type="revolute">
    <origin rpy="0 0 0" xyz="0 0 0.27"/>
    <parent link="${prefix}link_2"/>
    <child link="${prefix}link_3"/>
    <limit effort="100" lower="-1.91986" upper="1.22173" velocity="4.36332"/>
    <axis xyz="0 1 0"/>
    <dynamics damping="0.0" friction="0.0"/>
  </joint>
  <joint name="${prefix}joint_4" type="revolute">
    <origin rpy="0 0 0" xyz="0 0 0.07"/>
    <parent link="${prefix}link_3"/>
    <child link="${prefix}link_4"/>
    <limit effort="30" lower="-2.79253" upper="2.79253" velocity="5.58505"/>
    <axis xyz="1 0 0"/>
    <dynamics damping="0.0" friction="0.0"/>
  </joint>
  <joint name="${prefix}joint_5" type="revolute">
    <origin rpy="0 0 0" xyz="0.302 0 0"/>
    <parent link="${prefix}link_4"/>
    <child link="${prefix}link_5"/>
    <limit effort="30" lower="-2.094395" upper="2.094395" velocity="5.58505"/>
    <axis xyz="0 1 0"/>
    <dynamics damping="0.0" friction="0.0"/>
  </joint>
  <joint name="${prefix}joint_6" type="revolute">
    <origin rpy="0 0 0" xyz="0.072 0 0"/>
    <parent link="${prefix}link_5"/>
    <child link="${prefix}link_6"/>
    <limit effort="30" lower="-6.98132" upper="6.98132" velocity="7.33038"/>
    <axis xyz="1 0 0"/>
    <dynamics damping="0.0" friction="0.0"/>
  </joint>
  <joint name="${prefix}joint6-tool0" type="fixed">
    <parent link="${prefix}link_6"/>
    <child link="${prefix}tool0"/>
    <origin rpy="0 0 0" xyz="0 0 0"/>
  </joint>
  <!-- end of joint list -->

  <!-- ROS base_link to ABB World Coordinates transform -->
  <link name="${prefix}base" />
  <joint name="${prefix}base_link-base" type="fixed">
    <origin xyz="0 0 0" rpy="0 0 0"/>
    <parent link="${prefix}base_link"/>
    <child link="${prefix}base"/>
  </joint>
  </xacro:macro>
</robot>
